<?xml version="1.0" encoding="utf-8"?>
<robot name="jetauto" xmlns:xacro="http://ros.org/wiki/xacro" >
  <xacro:property name="M_PI"               value="3.1415926535897931"/>
  <xacro:property name="base_link_mass"     value="1.6" /> 
  <xacro:property name="base_link_w"        value="0.297"/>
  <xacro:property name="base_link_h"        value="0.145"/>
  <xacro:property name="base_link_d"        value="0.11255"/>

  <xacro:property name="wheel_link_mass"    value="0.1" />
  <xacro:property name="wheel_link_radius"  value="0.049"/>
  <xacro:property name="wheel_link_length"  value="0.04167"/>

  <xacro:include filename="$(find robotics_subject)/urdf/p3d_plugin.gazebo.xacro"/>


  <link name="base_footprint"/>

  <joint name="base_joint" type="fixed">
    <parent link="base_link"/>
    <child link="base_footprint"/>
    <origin xyz="0.0 0.0 0.005" rpy="0 0 0"/>
  </joint>

  <link
    name="base_link">
    <xacro:box_inertial m="${base_link_mass}" w="${base_link_w}" h="${base_link_h}" d="${base_link_d}"/>
    <visual>
      <origin
        xyz="0 0 0"
        rpy="0 0 0" />
      <geometry>
        <mesh
          filename="package://robotics_subject/models/jetauto/base_link.stl" />
      </geometry>
      <material name="green"/>
    </visual>
    <collision>
      <origin
        xyz="${base_link_w/2.0 - 0.14810} 0 ${0.126437/2 + 0.02362364}"
        rpy="0 0 0" />
      <geometry>
        <box size="${base_link_w} ${base_link_h} ${base_link_d}" />
      </geometry>
    </collision>
  </link>
  <link
    name="back_shell_link">
    <inertial>
      <origin
        xyz="-1.22838595456587E-05 0.00218574826309681 -0.0500522861933898"
        rpy="0 0 0" />
      <mass
        value="0.0663478534899862" />
      <inertia
        ixx="5.65277934912267E-05"
        ixy="-5.13394387877366E-11"
        ixz="-4.07561372273553E-11"
        iyy="4.33740893441632E-05"
        iyz="-5.43059341238134E-06"
        izz="6.86642544694324E-05" />
    </inertial>
    <visual>
      <origin
        xyz="0 0 0"
        rpy="0 0 0" />
      <geometry>
        <mesh
          filename="package://robotics_subject/models/jetauto/back_shell_link.stl" />
      </geometry>
      <material name="black">
      </material>
    </visual>
  </link>
  <joint
    name="back_shell_joint"
    type="fixed">
    <origin
      xyz="-0.076481 0 0.082796"
      rpy="-3.1416 0 1.5708" />
    <parent
      link="base_link" />
    <child
      link="back_shell_link" />
    <axis
      xyz="0 0 0" />
  </joint>
  <link
    name="wheel_right_front_link">
    <xacro:cylinder_inertial m="${wheel_link_mass}" r="${wheel_link_radius}" h="${wheel_link_length}" />
    <visual>
      <origin
        xyz="0 0 -0.004"
        rpy="${M_PI} 0 0" />
      <geometry>
        <mesh
          filename="package://robotics_subject/models/jetauto/wheel_right_front_link.stl" />
      </geometry>
      <material name="black"/>
    </visual>
    <collision>
      <origin
        xyz="0 0 -0.025"
        rpy="0 0 0" />
      <geometry>
        <cylinder length="${wheel_link_length}" radius="${wheel_link_radius}"/>
      </geometry>
    </collision>
  </link>
  <joint
    name="wheel_right_front_joint"
    type="continuous">
    <origin
      xyz="0.097397 -0.086125 0.04508"
      rpy="-1.5708 1.5708 0" />
    <parent
      link="base_link" />
    <child
      link="wheel_right_front_link" />
    <axis
      xyz="0 0 1"/>
  </joint>
  <link
    name="wheel_left_front_link">
    <xacro:cylinder_inertial m="${wheel_link_mass}" r="${wheel_link_radius}" h="${wheel_link_length}" />
    <visual>
      <origin
        xyz="0 0 0.004"
        rpy="${M_PI} 0 0" />
      <geometry>
        <mesh
          filename="package://robotics_subject/models/jetauto/wheel_left_front_link.stl" />
      </geometry>
      <material name="black"/>
    </visual>
    <collision>
      <origin
        xyz="0 0 0.025"
        rpy="0 0 0" />
      <geometry>
        <cylinder length="${wheel_link_length}" radius="${wheel_link_radius}"/>
      </geometry>
    </collision>
  </link>
  <joint
    name="wheel_left_front_joint"
    type="continuous">
    <origin
      xyz="0.097397 0.086125 0.04508"
      rpy="-1.5708 1.5708 0" />
    <parent
      link="base_link" />
    <child
      link="wheel_left_front_link" />
    <axis
      xyz="0 0 1"/>
  </joint>
  <link
    name="wheel_right_back_link">
    <xacro:cylinder_inertial m="${wheel_link_mass}" r="${wheel_link_radius}" h="${wheel_link_length}" />
    <visual>
      <origin
        xyz="0 0 -0.004"
        rpy="${M_PI} 0 0" />
      <geometry>
        <mesh
          filename="package://robotics_subject/models/jetauto/wheel_right_back_link.stl" />
      </geometry>
      <material name="black"/>
    </visual>
    <collision>
      <origin
        xyz="0 0 -0.025"
        rpy="0 0 0" />
      <geometry>
        <cylinder length="${wheel_link_length}" radius="${wheel_link_radius}"/>
      </geometry>
    </collision>
  </link>
  <joint
    name="wheel_right_back_joint"
    type="continuous">
    <origin
      xyz="-0.097397 -0.086125 0.04508"
      rpy="-1.5708 1.5708 0" />
    <parent
      link="base_link" />
    <child
      link="wheel_right_back_link" />
    <axis
      xyz="0 0 1"/>
  </joint>
  <link
    name="wheel_left_back_link">
    <xacro:cylinder_inertial m="${wheel_link_mass}" r="${wheel_link_radius}" h="${wheel_link_length}" />
    <visual>
      <origin
        xyz="0 0 0.004"
        rpy="${M_PI} 0 0" />
      <geometry>
        <mesh
          filename="package://robotics_subject/models/jetauto/wheel_left_back_link.stl" />
      </geometry>
      <material name="black"/>
    </visual>
    <collision>
      <origin
        xyz="0 0 0.025"
        rpy="0 0 0" />
      <geometry>
        <cylinder length="${wheel_link_length}" radius="${wheel_link_radius}"/>
      </geometry>
    </collision>
  </link>
  <joint
    name="wheel_left_back_joint"
    type="continuous">
    <origin
      xyz="-0.097397 0.086125 0.04508"
      rpy="-1.5708 1.5708 0" />
    <parent
      link="base_link" />
    <child
      link="wheel_left_back_link" />
    <axis
      xyz="0 0 1"/>
  </joint>

  <gazebo reference="wheel_left_back_link">
    <kp>5000000.0</kp>
    <kd>100.0</kd>
    <mu1>1.0</mu1>
    <mu2>1.0</mu2>
    <maxVel>1.0</maxVel>
    <minDepth>0.002</minDepth>
  </gazebo>

  <gazebo reference="wheel_left_front_link">
    <kp>5000000.0</kp>
    <kd>100.0</kd>
    <mu1>1.0</mu1>
    <mu2>1.0</mu2>
    <maxVel>1.0</maxVel>
    <minDepth>0.002</minDepth>
  </gazebo>

  <gazebo reference="wheel_right_back_link">
    <kp>5000000.0</kp>
    <kd>100.0</kd>
    <mu1>1.0</mu1>
    <mu2>1.0</mu2>
    <maxVel>1.0</maxVel>
    <minDepth>0.002</minDepth>
  </gazebo>

  <gazebo reference="wheel_right_front_link">
    <kp>5000000.0</kp>
    <kd>100.0</kd>
    <mu1>1.0</mu1>
    <mu2>1.0</mu2>
    <maxVel>1.0</maxVel>
    <minDepth>0.002</minDepth>
  </gazebo>

  <xacro:p3d_plugin_macro 
    parent="base_link"
    update_rate="100"
    topic_name="odometry/ground_truth"
    mass="0.00001"
    body_name="base_link"
    frame_name="base_footprint"
    noise="0"
    xyz_offset="0 0 0"
    rpy_offset="0 0 0">
    <inertia ixx="0.00001" ixy="0" ixz="0" iyy="0.00001" iyz="0" izz="0.00001"/>
    <origin xyz="0 0 0" rpy="0 0 0"/>
  </xacro:p3d_plugin_macro>

  <gazebo>
    <plugin name="gazebo_ros_mecanum_diff_drive" filename="libgazebo_mecanum_drive.so">
      <ros>
        <remapping>cmd_vel:=/jetauto/cmd_vel</remapping>
        <remapping>odom:=/jetauto/odometry/unfiltered</remapping>
      </ros>
      <commandTopic>cmd_vel</commandTopic>
      <odometryTopic>odom</odometryTopic>
      <odometryFrame>odom</odometryFrame>
      <robotBaseFrame>base_link</robotBaseFrame>
      <LeftRear>wheel_left_back_joint</LeftRear>
      <LeftFront>wheel_left_front_joint</LeftFront>
      <RightFront>wheel_right_front_joint</RightFront>
      <RightRear>wheel_right_back_joint</RightRear>
      <odometryRate>100</odometryRate>      
      <publishWheelTF>false</publishWheelTF>
      <publishOdomTF>true</publishOdomTF>
      <WheelTorque>5</WheelTorque>
      <WheelSeparationW>0.172</WheelSeparationW>
      <WheelSeparationL>0.195</WheelSeparationL>
      <wheelAccel>5</wheelAccel>
      <wheelDiameter>0.098</wheelDiameter>
      <publishOdom>true</publishOdom>
      <isRollerModel>false</isRollerModel>
    </plugin>
  </gazebo>
</robot>